<?xml version="1.0" encoding="UTF-8"?>
<!-- Generated by org.testng.reporters.JUnitReportReporter -->
<testsuite hostname="LAPTOP-6PTS3HBQ" failures="0" tests="16" name="Test_ng.NewTestng_fet" time="0.058" errors="2" timestamp="2025-07-24T19:40:11 IST" skipped="0">
  <testcase classname="Test_ng.NewTestng_fet" name="add" time="0.012">
    <error message="
Method NewTestng_fet.add()[pri:0, instance:Test_ng.NewTestng_fet@2d52216b] should have thrown an exception of type class java.lang.NullPointerException" type="org.testng.TestException">
      <![CDATA[org.testng.TestException: 
Method NewTestng_fet.add()[pri:0, instance:Test_ng.NewTestng_fet@2d52216b] should have thrown an exception of type class java.lang.NullPointerException
at org.testng.internal.invokers.ExpectedExceptionsHolder.noException(ExpectedExceptionsHolder.java:81)
at org.testng.internal.invokers.TestInvoker.considerExceptions(TestInvoker.java:873)
at org.testng.internal.invokers.TestInvoker.invokeMethod(TestInvoker.java:731)
at org.testng.internal.invokers.TestInvoker.invokeTestMethod(TestInvoker.java:221)
at org.testng.internal.invokers.MethodRunner.runInSequence(MethodRunner.java:50)
at org.testng.internal.invokers.TestInvoker$MethodInvocationAgent.invoke(TestInvoker.java:969)
at org.testng.internal.invokers.TestInvoker.invokeTestMethods(TestInvoker.java:194)
at org.testng.internal.invokers.TestMethodWorker.invokeTestMethods(TestMethodWorker.java:148)
at org.testng.internal.invokers.TestMethodWorker.run(TestMethodWorker.java:128)
at java.base/java.util.ArrayList.forEach(ArrayList.java:1511)
at org.testng.TestRunner.privateRun(TestRunner.java:829)
at org.testng.TestRunner.run(TestRunner.java:602)
at org.testng.SuiteRunner.runTest(SuiteRunner.java:437)
at org.testng.SuiteRunner.runSequentially(SuiteRunner.java:431)
at org.testng.SuiteRunner.privateRun(SuiteRunner.java:391)
at org.testng.SuiteRunner.run(SuiteRunner.java:330)
at org.testng.SuiteRunnerWorker.runSuite(SuiteRunnerWorker.java:52)
at org.testng.SuiteRunnerWorker.run(SuiteRunnerWorker.java:95)
at org.testng.TestNG.runSuitesSequentially(TestNG.java:1256)
at org.testng.TestNG.runSuitesLocally(TestNG.java:1176)
at org.testng.TestNG.runSuites(TestNG.java:1099)
at org.testng.TestNG.run(TestNG.java:1067)
at org.testng.remote.AbstractRemoteTestNG.run(AbstractRemoteTestNG.java:115)
at org.testng.remote.RemoteTestNG.initAndRun(RemoteTestNG.java:251)
at org.testng.remote.RemoteTestNG.main(RemoteTestNG.java:77)
]]>
    </error>
  </testcase> <!-- add -->
  <system-out/>
  <testcase classname="Test_ng.NewTestng_fet" name="jyoti" time="0.003"/>
  <system-out/>
  <testcase classname="Test_ng.NewTestng_fet" name="jyoti" time="0.004"/>
  <system-out/>
  <testcase classname="Test_ng.NewTestng_fet" name="jyoti" time="0.002"/>
  <system-out/>
  <testcase classname="Test_ng.NewTestng_fet" name="search" time="0.003"/>
  <system-out/>
  <testcase classname="Test_ng.NewTestng_fet" name="sum" time="0.003">
    <error message="
Method NewTestng_fet.sum()[pri:0, instance:Test_ng.NewTestng_fet@2d52216b] should have thrown an exception of type class java.lang.ArithmeticException" type="org.testng.TestException">
      <![CDATA[org.testng.TestException: 
Method NewTestng_fet.sum()[pri:0, instance:Test_ng.NewTestng_fet@2d52216b] should have thrown an exception of type class java.lang.ArithmeticException
at org.testng.internal.invokers.ExpectedExceptionsHolder.noException(ExpectedExceptionsHolder.java:81)
at org.testng.internal.invokers.TestInvoker.considerExceptions(TestInvoker.java:873)
at org.testng.internal.invokers.TestInvoker.invokeMethod(TestInvoker.java:731)
at org.testng.internal.invokers.TestInvoker.invokeTestMethod(TestInvoker.java:221)
at org.testng.internal.invokers.MethodRunner.runInSequence(MethodRunner.java:50)
at org.testng.internal.invokers.TestInvoker$MethodInvocationAgent.invoke(TestInvoker.java:969)
at org.testng.internal.invokers.TestInvoker.invokeTestMethods(TestInvoker.java:194)
at org.testng.internal.invokers.TestMethodWorker.invokeTestMethods(TestMethodWorker.java:148)
at org.testng.internal.invokers.TestMethodWorker.run(TestMethodWorker.java:128)
at java.base/java.util.ArrayList.forEach(ArrayList.java:1511)
at org.testng.TestRunner.privateRun(TestRunner.java:829)
at org.testng.TestRunner.run(TestRunner.java:602)
at org.testng.SuiteRunner.runTest(SuiteRunner.java:437)
at org.testng.SuiteRunner.runSequentially(SuiteRunner.java:431)
at org.testng.SuiteRunner.privateRun(SuiteRunner.java:391)
at org.testng.SuiteRunner.run(SuiteRunner.java:330)
at org.testng.SuiteRunnerWorker.runSuite(SuiteRunnerWorker.java:52)
at org.testng.SuiteRunnerWorker.run(SuiteRunnerWorker.java:95)
at org.testng.TestNG.runSuitesSequentially(TestNG.java:1256)
at org.testng.TestNG.runSuitesLocally(TestNG.java:1176)
at org.testng.TestNG.runSuites(TestNG.java:1099)
at org.testng.TestNG.run(TestNG.java:1067)
at org.testng.remote.AbstractRemoteTestNG.run(AbstractRemoteTestNG.java:115)
at org.testng.remote.RemoteTestNG.initAndRun(RemoteTestNG.java:251)
at org.testng.remote.RemoteTestNG.main(RemoteTestNG.java:77)
]]>
    </error>
  </testcase> <!-- sum -->
  <system-out/>
  <testcase classname="Test_ng.NewTestng_fet" name="jyoti" time="0.002"/>
  <system-out/>
  <testcase classname="Test_ng.NewTestng_fet" name="jyoti" time="0.003"/>
  <system-out/>
  <testcase classname="Test_ng.NewTestng_fet" name="jyoti" time="0.004"/>
  <system-out/>
  <testcase classname="Test_ng.NewTestng_fet" name="jyoti" time="0.001"/>
  <system-out/>
  <testcase classname="Test_ng.NewTestng_fet" name="addtocart" time="0.002"/>
  <system-out/>
  <testcase classname="Test_ng.NewTestng_fet" name="jyoti" time="0.004"/>
  <system-out/>
  <testcase classname="Test_ng.NewTestng_fet" name="jyoti" time="0.007"/>
  <system-out/>
  <testcase classname="Test_ng.NewTestng_fet" name="jyoti" time="0.003"/>
  <system-out/>
  <testcase classname="Test_ng.NewTestng_fet" name="buy" time="0.002"/>
  <system-out/>
  <testcase classname="Test_ng.NewTestng_fet" name="payment" time="0.003"/>
  <system-out/>
</testsuite> <!-- Test_ng.NewTestng_fet -->
